Workbook
Name Statement: 'P&L_2018 & 2019'!$B:$G

Sheet COA
A1: Account_key | B1: Report | C1: Class | D1: SubClass | E1: SubClass2 | F1: Account | G1: SubAccount
A2: 10 | B2: Balance Sheet | C2: Assets | D2: Assets | E2: Current Assets | F2: Cash & Cash Equivalents | G2: Cash at Bank
A3: 20 | B3: Balance Sheet | C3: Assets | D3: Assets | E3: Current Assets | F3: Cash & Cash Equivalents | G3: Cash in hand
A4: 30 | B4: Balance Sheet | C4: Assets | D4: Assets | E4: Current Assets | F4: Receivables | G4: Trade Receivables
A5: 40 | B5: Balance Sheet | C5: Assets | D5: Assets | E5: Current Assets | F5: Receivables | G5: Other Receivables
A6: 41 | B6: Balance Sheet | C6: Assets | D6: Assets | E6: Current Assets | F6: Receivables | G6: Interest Receivable
A7: 42 | B7: Balance Sheet | C7: Assets | D7: Assets | E7: Current Assets | F7: Receivables | G7: Dividend Receivable
A8: 50 | B8: Balance Sheet | C8: Assets | D8: Assets | E8: Current Assets | F8: Receivables | G8: Allowance for Bad Debt
A9: 60 | B9: Balance Sheet | C9: Assets | D9: Assets | E9: Current Assets | F9: Inventory | G9: Inventory
A10: 70 | B10: Balance Sheet | C10: Assets | D10: Assets | E10: Current Assets | F10: Other Current Assets | G10: Prepaid Expenses
A11: 75 | B11: Balance Sheet | C11: Assets | D11: Assets | E11: Current Assets | F11: Investments | G11: Securities
A12: 80 | B12: Balance Sheet | C12: Assets | D12: Assets | E12: Non-Current Assets | F12: Property, Plant, & Equipment | G12: Land & Buildings
A13: 90 | B13: Balance Sheet | C13: Assets | D13: Assets | E13: Non-Current Assets | F13: Property, Plant, & Equipment | G13: Office Furniture & Equipment
... A55: 1010 | B55: Adjusting | C55: Adjusting | D55: Adjusting | E55: Adjusting | F55: Adjusting | G55: Adjusting

Sheet Calendar
A1: Date | B1: Year | C1: Quarter | D1: Month | E1: Day
A2: 43101 | B2: 2018 | C2: Qtr 1 | D2: Jan | E2: Mon
A3: 43102 | B3: 2018 | C3: Qtr 1 | D3: Jan | E3: Tue
A4: 43103 | B4: 2018 | C4: Qtr 1 | D4: Jan | E4: Wed
A5: 43104 | B5: 2018 | C5: Qtr 1 | D5: Jan | E5: Thu
A6: 43105 | B6: 2018 | C6: Qtr 1 | D6: Jan | E6: Fri
A7: 43106 | B7: 2018 | C7: Qtr 1 | D7: Jan | E7: Sat
A8: 43107 | B8: 2018 | C8: Qtr 1 | D8: Jan | E8: Sun
A9: 43108 | B9: 2018 | C9: Qtr 1 | D9: Jan | E9: Mon
A10: 43109 | B10: 2018 | C10: Qtr 1 | D10: Jan | E10: Tue
A11: 43110 | B11: 2018 | C11: Qtr 1 | D11: Jan | E11: Wed
A12: 43111 | B12: 2018 | C12: Qtr 1 | D12: Jan | E12: Thu
A13: 43112 | B13: 2018 | C13: Qtr 1 | D13: Jan | E13: Fri
... A731: 43830 | B731: 2019 | C731: Qtr 4 | D731: Dec | E731: Tue

Sheet Territory
A1: Territory_key | B1: Country | C1: Region
A2: 1 | B2: USA | C2: North America
A3: 2 | B3: Canada | C3: North America
A4: 3 | B4: UK | C4: Europe
A5: 4 | B5: Germany | C5: Europe
A6: 5 | B6: France | C6: Europe
A7: 6 | B7: Australia | C7: Oceania
A8: 7 | B8: New Zealand | C8: Oceania

Sheet GL
A1: EntryNo | B1: Date | C1: Territory_key | D1: Account_key | E1: Details | F1: Amount | G1: Catagorization | H1: SubClass | I1: SubClass2 | J1: Account | K1: Year
A2: 1.1 | B2: 43101 | C2: 1 | D2: 230 | E2: Cost of Sales | F2: -884 | G2: =_xlfn.XLOOKUP(tbl_GL[[#This Row],[Account_key]],tbl_COA[Account_key],tbl_COA[Class],"Not Found") -> Trading account | H2: =_xlfn.XLOOKUP(tbl_GL[[#This Row],[Account_key]],tbl_COA[Account_key],tbl_COA[SubClass],"Not Found") -> Cost of Sales | I2: =_xlfn.XLOOKUP(tbl_GL[[#This Row],[Account_key]],tbl_COA[Account_key],tbl_COA[SubClass2],"Not Found") -> Cost of Sales | J2: =_xlfn.XLOOKUP(tbl_GL[[#This Row],[Account_key]],tbl_COA[Account_key],tbl_COA[SubAccount],,0) -> Cost of Sales | K2: =YEAR(tbl_GL[[#This Row],[Date]]) -> 2018
A3: 1.2 | B3: 43101 | C3: 1 | D3: 60 | E3: Cost of Sales | F3: -884 | G3: =_xlfn.XLOOKUP(tbl_GL[[#This Row],[Account_key]],tbl_COA[Account_key],tbl_COA[Class],"Not Found") -> Assets | H3: =_xlfn.XLOOKUP(tbl_GL[[#This Row],[Account_key]],tbl_COA[Account_key],tbl_COA[SubClass],"Not Found") -> Assets | I3: =_xlfn.XLOOKUP(tbl_GL[[#This Row],[Account_key]],tbl_COA[Account_key],tbl_COA[SubClass2],"Not Found") -> Current Assets | J3: =_xlfn.XLOOKUP(tbl_GL[[#This Row],[Account_key]],tbl_COA[Account_key],tbl_COA[SubAccount],,0) -> Inventory | K3: =YEAR(tbl_GL[[#This Row],[Date]]) -> 2018
A4: 2.1 | B4: 43101 | C4: 1 | D4: 230 | E4: Cost of Sales | F4: -1120 | G4: =_xlfn.XLOOKUP(tbl_GL[[#This Row],[Account_key]],tbl_COA[Account_key],tbl_COA[Class],"Not Found") -> Trading account | H4: =_xlfn.XLOOKUP(tbl_GL[[#This Row],[Account_key]],tbl_COA[Account_key],tbl_COA[SubClass],"Not Found") -> Cost of Sales | I4: =_xlfn.XLOOKUP(tbl_GL[[#This Row],[Account_key]],tbl_COA[Account_key],tbl_COA[SubClass2],"Not Found") -> Cost of Sales | J4: =_xlfn.XLOOKUP(tbl_GL[[#This Row],[Account_key]],tbl_COA[Account_key],tbl_COA[SubAccount],,0) -> Cost of Sales | K4: =YEAR(tbl_GL[[#This Row],[Date]]) -> 2018
A5: 2.2 | B5: 43101 | C5: 1 | D5: 60 | E5: Cost of Sales | F5: -1120 | G5: =_xlfn.XLOOKUP(tbl_GL[[#This Row],[Account_key]],tbl_COA[Account_key],tbl_COA[Class],"Not Found") -> Assets | H5: =_xlfn.XLOOKUP(tbl_GL[[#This Row],[Account_key]],tbl_COA[Account_key],tbl_COA[SubClass],"Not Found") -> Assets | I5: =_xlfn.XLOOKUP(tbl_GL[[#This Row],[Account_key]],tbl_COA[Account_key],tbl_COA[SubClass2],"Not Found") -> Current Assets | J5: =_xlfn.XLOOKUP(tbl_GL[[#This Row],[Account_key]],tbl_COA[Account_key],tbl_COA[SubAccount],,0) -> Inventory | K5: =YEAR(tbl_GL[[#This Row],[Date]]) -> 2018
A6: 3.1 | B6: 43101 | C6: 1 | D6: 280 | E6: Credit Expenses | F6: -2394 | G6: =_xlfn.XLOOKUP(tbl_GL[[#This Row],[Account_key]],tbl_COA[Account_key],tbl_COA[Class],"Not Found") -> Operating account | H6: =_xlfn.XLOOKUP(tbl_GL[[#This Row],[Account_key]],tbl_COA[Account_key],tbl_COA[SubClass],"Not Found") -> Operating Expenses | I6: =_xlfn.XLOOKUP(tbl_GL[[#This Row],[Account_key]],tbl_COA[Account_key],tbl_COA[SubClass2],"Not Found") -> Marketing | J6: =_xlfn.XLOOKUP(tbl_GL[[#This Row],[Account_key]],tbl_COA[Account_key],tbl_COA[SubAccount],,0) -> Advertisements | K6: =YEAR(tbl_GL[[#This Row],[Date]]) -> 2018
A7: 3.2 | B7: 43101 | C7: 1 | D7: 120 | E7: Credit Expenses | F7: 2394 | G7: =_xlfn.XLOOKUP(tbl_GL[[#This Row],[Account_key]],tbl_COA[Account_key],tbl_COA[Class],"Not Found") -> Liabilities and Owners Equity | H7: =_xlfn.XLOOKUP(tbl_GL[[#This Row],[Account_key]],tbl_COA[Account_key],tbl_COA[SubClass],"Not Found") -> Liabilities | I7: =_xlfn.XLOOKUP(tbl_GL[[#This Row],[Account_key]],tbl_COA[Account_key],tbl_COA[SubClass2],"Not Found") -> Current Liabilities | J7: =_xlfn.XLOOKUP(tbl_GL[[#This Row],[Account_key]],tbl_COA[Account_key],tbl_COA[SubAccount],,0) -> Accrued Expenses | K7: =YEAR(tbl_GL[[#This Row],[Date]]) -> 2018
A8: 4.1 | B8: 43101 | C8: 1 | D8: 210 | E8: Credit Sales | F8: 2948 | G8: =_xlfn.XLOOKUP(tbl_GL[[#This Row],[Account_key]],tbl_COA[Account_key],tbl_COA[Class],"Not Found") -> Trading account | H8: =_xlfn.XLOOKUP(tbl_GL[[#This Row],[Account_key]],tbl_COA[Account_key],tbl_COA[SubClass],"Not Found") -> Sales | I8: =_xlfn.XLOOKUP(tbl_GL[[#This Row],[Account_key]],tbl_COA[Account_key],tbl_COA[SubClass2],"Not Found") -> Sales | J8: =_xlfn.XLOOKUP(tbl_GL[[#This Row],[Account_key]],tbl_COA[Account_key],tbl_COA[SubAccount],,0) -> Sales | K8: =YEAR(tbl_GL[[#This Row],[Date]]) -> 2018
A9: 4.2 | B9: 43101 | C9: 1 | D9: 30 | E9: Credit Sales | F9: 2948 | G9: =_xlfn.XLOOKUP(tbl_GL[[#This Row],[Account_key]],tbl_COA[Account_key],tbl_COA[Class],"Not Found") -> Assets | H9: =_xlfn.XLOOKUP(tbl_GL[[#This Row],[Account_key]],tbl_COA[Account_key],tbl_COA[SubClass],"Not Found") -> Assets | I9: =_xlfn.XLOOKUP(tbl_GL[[#This Row],[Account_key]],tbl_COA[Account_key],tbl_COA[SubClass2],"Not Found") -> Current Assets | J9: =_xlfn.XLOOKUP(tbl_GL[[#This Row],[Account_key]],tbl_COA[Account_key],tbl_COA[SubAccount],,0) -> Trade Receivables | K9: =YEAR(tbl_GL[[#This Row],[Date]]) -> 2018
A10: 5.1 | B10: 43101 | C10: 1 | D10: 210 | E10: Cash Sales | F10: 3734 | G10: =_xlfn.XLOOKUP(tbl_GL[[#This Row],[Account_key]],tbl_COA[Account_key],tbl_COA[Class],"Not Found") -> Trading account | H10: =_xlfn.XLOOKUP(tbl_GL[[#This Row],[Account_key]],tbl_COA[Account_key],tbl_COA[SubClass],"Not Found") -> Sales | I10: =_xlfn.XLOOKUP(tbl_GL[[#This Row],[Account_key]],tbl_COA[Account_key],tbl_COA[SubClass2],"Not Found") -> Sales | J10: =_xlfn.XLOOKUP(tbl_GL[[#This Row],[Account_key]],tbl_COA[Account_key],tbl_COA[SubAccount],,0) -> Sales | K10: =YEAR(tbl_GL[[#This Row],[Date]]) -> 2018
A11: 5.2 | B11: 43101 | C11: 1 | D11: 10 | E11: Cash Sales | F11: 3734 | G11: =_xlfn.XLOOKUP(tbl_GL[[#This Row],[Account_key]],tbl_COA[Account_key],tbl_COA[Class],"Not Found") -> Assets | H11: =_xlfn.XLOOKUP(tbl_GL[[#This Row],[Account_key]],tbl_COA[Account_key],tbl_COA[SubClass],"Not Found") -> Assets | I11: =_xlfn.XLOOKUP(tbl_GL[[#This Row],[Account_key]],tbl_COA[Account_key],tbl_COA[SubClass2],"Not Found") -> Current Assets | J11: =_xlfn.XLOOKUP(tbl_GL[[#This Row],[Account_key]],tbl_COA[Account_key],tbl_COA[SubAccount],,0) -> Cash at Bank | K11: =YEAR(tbl_GL[[#This Row],[Date]]) -> 2018
A12: 6.1 | B12: 43101 | C12: 1 | D12: 230 | E12: Cost of Sales | F12: -4371 | G12: =_xlfn.XLOOKUP(tbl_GL[[#This Row],[Account_key]],tbl_COA[Account_key],tbl_COA[Class],"Not Found") -> Trading account | H12: =_xlfn.XLOOKUP(tbl_GL[[#This Row],[Account_key]],tbl_COA[Account_key],tbl_COA[SubClass],"Not Found") -> Cost of Sales | I12: =_xlfn.XLOOKUP(tbl_GL[[#This Row],[Account_key]],tbl_COA[Account_key],tbl_COA[SubClass2],"Not Found") -> Cost of Sales | J12: =_xlfn.XLOOKUP(tbl_GL[[#This Row],[Account_key]],tbl_COA[Account_key],tbl_COA[SubAccount],,0) -> Cost of Sales | K12: =YEAR(tbl_GL[[#This Row],[Date]]) -> 2018
A13: 6.2 | B13: 43101 | C13: 1 | D13: 60 | E13: Cost of Sales | F13: -4371 | G13: =_xlfn.XLOOKUP(tbl_GL[[#This Row],[Account_key]],tbl_COA[Account_key],tbl_COA[Class],"Not Found") -> Assets | H13: =_xlfn.XLOOKUP(tbl_GL[[#This Row],[Account_key]],tbl_COA[Account_key],tbl_COA[SubClass],"Not Found") -> Assets | I13: =_xlfn.XLOOKUP(tbl_GL[[#This Row],[Account_key]],tbl_COA[Account_key],tbl_COA[SubClass2],"Not Found") -> Current Assets | J13: =_xlfn.XLOOKUP(tbl_GL[[#This Row],[Account_key]],tbl_COA[Account_key],tbl_COA[SubAccount],,0) -> Inventory | K13: =YEAR(tbl_GL[[#This Row],[Date]]) -> 2018
... A18216: 49.1 | B18216: 43131 | C18216: 1 | D18216: 200 | E18216: Transfer of Net Profit to Retained Earnings | F18216: 5858 | G18216: =_xlfn.XLOOKUP(tbl_GL[[#This Row],[Account_key]],tbl_COA[Account_key],tbl_COA[Class],"Not Found") -> Liabilities and Owners Equity | H18216: =_xlfn.XLOOKUP(tbl_GL[[#This Row],[Account_key]],tbl_COA[Account_key],tbl_COA[SubClass],"Not Found") -> Owners Equity | I18216: =_xlfn.XLOOKUP(tbl_GL[[#This Row],[Account_key]],tbl_COA[Account_key],tbl_COA[SubClass2],"Not Found") -> Retained Earnings | J18216: =_xlfn.XLOOKUP(tbl_GL[[#This Row],[Account_key]],tbl_COA[Account_key],tbl_COA[SubAccount],,0) -> Retained Earnings | K18216: =YEAR(tbl_GL[[#This Row],[Date]]) -> 2018
A18217: 93.1 | B18217: 43159 | C18217: =C18216 -> 1 | D18217: 200 | E18217: Transfer of Net Profit to Retained Earnings | F18217: -4784 | G18217: =_xlfn.XLOOKUP(tbl_GL[[#This Row],[Account_key]],tbl_COA[Account_key],tbl_COA[Class],"Not Found") -> Liabilities and Owners Equity | H18217: =_xlfn.XLOOKUP(tbl_GL[[#This Row],[Account_key]],tbl_COA[Account_key],tbl_COA[SubClass],"Not Found") -> Owners Equity | I18217: =_xlfn.XLOOKUP(tbl_GL[[#This Row],[Account_key]],tbl_COA[Account_key],tbl_COA[SubClass2],"Not Found") -> Retained Earnings | J18217: =_xlfn.XLOOKUP(tbl_GL[[#This Row],[Account_key]],tbl_COA[Account_key],tbl_COA[SubAccount],,0) -> Retained Earnings | K18217: =YEAR(tbl_GL[[#This Row],[Date]]) -> 2018
A18218: 142.1 | B18218: 43190 | C18218: =C18217 -> 1 | D18218: 200 | E18218: Transfer of Net Profit to Retained Earnings | F18218: -2196 | G18218: =_xlfn.XLOOKUP(tbl_GL[[#This Row],[Account_key]],tbl_COA[Account_key],tbl_COA[Class],"Not Found") -> Liabilities and Owners Equity | H18218: =_xlfn.XLOOKUP(tbl_GL[[#This Row],[Account_key]],tbl_COA[Account_key],tbl_COA[SubClass],"Not Found") -> Owners Equity | I18218: =_xlfn.XLOOKUP(tbl_GL[[#This Row],[Account_key]],tbl_COA[Account_key],tbl_COA[SubClass2],"Not Found") -> Retained Earnings | J18218: =_xlfn.XLOOKUP(tbl_GL[[#This Row],[Account_key]],tbl_COA[Account_key],tbl_COA[SubAccount],,0) -> Retained Earnings | K18218: =YEAR(tbl_GL[[#This Row],[Date]]) -> 2018
A18219: 200.1 | B18219: 43220 | C18219: =C18218 -> 1 | D18219: 200 | E18219: Transfer of Net Profit to Retained Earnings | F18219: 8388 | G18219: =_xlfn.XLOOKUP(tbl_GL[[#This Row],[Account_key]],tbl_COA[Account_key],tbl_COA[Class],"Not Found") -> Liabilities and Owners Equity | H18219: =_xlfn.XLOOKUP(tbl_GL[[#This Row],[Account_key]],tbl_COA[Account_key],tbl_COA[SubClass],"Not Found") -> Owners Equity | I18219: =_xlfn.XLOOKUP(tbl_GL[[#This Row],[Account_key]],tbl_COA[Account_key],tbl_COA[SubClass2],"Not Found") -> Retained Earnings | J18219: =_xlfn.XLOOKUP(tbl_GL[[#This Row],[Account_key]],tbl_COA[Account_key],tbl_COA[SubAccount],,0) -> Retained Earnings | K18219: =YEAR(tbl_GL[[#This Row],[Date]]) -> 2018
A18220: 250.1 | B18220: 43251 | C18220: =C18219 -> 1 | D18220: 200 | E18220: Transfer of Net Profit to Retained Earnings | F18220: 4892 | G18220: =_xlfn.XLOOKUP(tbl_GL[[#This Row],[Account_key]],tbl_COA[Account_key],tbl_COA[Class],"Not Found") -> Liabilities and Owners Equity | H18220: =_xlfn.XLOOKUP(tbl_GL[[#This Row],[Account_key]],tbl_COA[Account_key],tbl_COA[SubClass],"Not Found") -> Owners Equity | I18220: =_xlfn.XLOOKUP(tbl_GL[[#This Row],[Account_key]],tbl_COA[Account_key],tbl_COA[SubClass2],"Not Found") -> Retained Earnings | J18220: =_xlfn.XLOOKUP(tbl_GL[[#This Row],[Account_key]],tbl_COA[Account_key],tbl_COA[SubAccount],,0) -> Retained Earnings | K18220: =YEAR(tbl_GL[[#This Row],[Date]]) -> 2018
A18221: 301.1 | B18221: 43281 | C18221: =C18220 -> 1 | D18221: 200 | E18221: Transfer of Net Profit to Retained Earnings | F18221: 5376 | G18221: =_xlfn.XLOOKUP(tbl_GL[[#This Row],[Account_key]],tbl_COA[Account_key],tbl_COA[Class],"Not Found") -> Liabilities and Owners Equity | H18221: =_xlfn.XLOOKUP(tbl_GL[[#This Row],[Account_key]],tbl_COA[Account_key],tbl_COA[SubClass],"Not Found") -> Owners Equity | I18221: =_xlfn.XLOOKUP(tbl_GL[[#This Row],[Account_key]],tbl_COA[Account_key],tbl_COA[SubClass2],"Not Found") -> Retained Earnings | J18221: =_xlfn.XLOOKUP(tbl_GL[[#This Row],[Account_key]],tbl_COA[Account_key],tbl_COA[SubAccount],,0) -> Retained Earnings | K18221: =YEAR(tbl_GL[[#This Row],[Date]]) -> 2018
A18222: 363.1 | B18222: 43312 | C18222: =C18221 -> 1 | D18222: 200 | E18222: Transfer of Net Profit to Retained Earnings | F18222: 25094 | G18222: =_xlfn.XLOOKUP(tbl_GL[[#This Row],[Account_key]],tbl_COA[Account_key],tbl_COA[Class],"Not Found") -> Liabilities and Owners Equity | H18222: =_xlfn.XLOOKUP(tbl_GL[[#This Row],[Account_key]],tbl_COA[Account_key],tbl_COA[SubClass],"Not Found") -> Owners Equity | I18222: =_xlfn.XLOOKUP(tbl_GL[[#This Row],[Account_key]],tbl_COA[Account_key],tbl_COA[SubClass2],"Not Found") -> Retained Earnings | J18222: =_xlfn.XLOOKUP(tbl_GL[[#This Row],[Account_key]],tbl_COA[Account_key],tbl_COA[SubAccount],,0) -> Retained Earnings | K18222: =YEAR(tbl_GL[[#This Row],[Date]]) -> 2018
A18223: 422.1 | B18223: 43343 | C18223: =C18222 -> 1 | D18223: 200 | E18223: Transfer of Net Profit to Retained Earnings | F18223: 23376 | G18223: =_xlfn.XLOOKUP(tbl_GL[[#This Row],[Account_key]],tbl_COA[Account_key],tbl_COA[Class],"Not Found") -> Liabilities and Owners Equity | H18223: =_xlfn.XLOOKUP(tbl_GL[[#This Row],[Account_key]],tbl_COA[Account_key],tbl_COA[SubClass],"Not Found") -> Owners Equity | I18223: =_xlfn.XLOOKUP(tbl_GL[[#This Row],[Account_key]],tbl_COA[Account_key],tbl_COA[SubClass2],"Not Found") -> Retained Earnings | J18223: =_xlfn.XLOOKUP(tbl_GL[[#This Row],[Account_key]],tbl_COA[Account_key],tbl_COA[SubAccount],,0) -> Retained Earnings | K18223: =YEAR(tbl_GL[[#This Row],[Date]]) -> 2018
A18224: 478.1 | B18224: 43373 | C18224: =C18223 -> 1 | D18224: 200 | E18224: Transfer of Net Profit to Retained Earnings | F18224: 20542 | G18224: =_xlfn.XLOOKUP(tbl_GL[[#This Row],[Account_key]],tbl_COA[Account_key],tbl_COA[Class],"Not Found") -> Liabilities and Owners Equity | H18224: =_xlfn.XLOOKUP(tbl_GL[[#This Row],[Account_key]],tbl_COA[Account_key],tbl_COA[SubClass],"Not Found") -> Owners Equity | I18224: =_xlfn.XLOOKUP(tbl_GL[[#This Row],[Account_key]],tbl_COA[Account_key],tbl_COA[SubClass2],"Not Found") -> Retained Earnings | J18224: =_xlfn.XLOOKUP(tbl_GL[[#This Row],[Account_key]],tbl_COA[Account_key],tbl_COA[SubAccount],,0) -> Retained Earnings | K18224: =YEAR(tbl_GL[[#This Row],[Date]]) -> 2018
A18225: 539.1 | B18225: 43404 | C18225: =C18224 -> 1 | D18225: 200 | E18225: Transfer of Net Profit to Retained Earnings | F18225: 27758 | G18225: =_xlfn.XLOOKUP(tbl_GL[[#This Row],[Account_key]],tbl_COA[Account_key],tbl_COA[Class],"Not Found") -> Liabilities and Owners Equity | H18225: =_xlfn.XLOOKUP(tbl_GL[[#This Row],[Account_key]],tbl_COA[Account_key],tbl_COA[SubClass],"Not Found") -> Owners Equity | I18225: =_xlfn.XLOOKUP(tbl_GL[[#This Row],[Account_key]],tbl_COA[Account_key],tbl_COA[SubClass2],"Not Found") -> Retained Earnings | J18225: =_xlfn.XLOOKUP(tbl_GL[[#This Row],[Account_key]],tbl_COA[Account_key],tbl_COA[SubAccount],,0) -> Retained Earnings | K18225: =YEAR(tbl_GL[[#This Row],[Date]]) -> 2018
A18226: 601.1 | B18226: 43434 | C18226: =C18225 -> 1 | D18226: 200 | E18226: Transfer of Net Profit to Retained Earnings | F18226: 50740 | G18226: =_xlfn.XLOOKUP(tbl_GL[[#This Row],[Account_key]],tbl_COA[Account_key],tbl_COA[Class],"Not Found") -> Liabilities and Owners Equity | H18226: =_xlfn.XLOOKUP(tbl_GL[[#This Row],[Account_key]],tbl_COA[Account_key],tbl_COA[SubClass],"Not Found") -> Owners Equity | I18226: =_xlfn.XLOOKUP(tbl_GL[[#This Row],[Account_key]],tbl_COA[Account_key],tbl_COA[SubClass2],"Not Found") -> Retained Earnings | J18226: =_xlfn.XLOOKUP(tbl_GL[[#This Row],[Account_key]],tbl_COA[Account_key],tbl_COA[SubAccount],,0) -> Retained Earnings | K18226: =YEAR(tbl_GL[[#This Row],[Date]]) -> 2018
A18227: 654.1 | B18227: 43465 | C18227: =C18226 -> 1 | D18227: 200 | E18227: Transfer of Net Profit to Retained Earnings | F18227: 37525 | G18227: =_xlfn.XLOOKUP(tbl_GL[[#This Row],[Account_key]],tbl_COA[Account_key],tbl_COA[Class],"Not Found") -> Liabilities and Owners Equity | H18227: =_xlfn.XLOOKUP(tbl_GL[[#This Row],[Account_key]],tbl_COA[Account_key],tbl_COA[SubClass],"Not Found") -> Owners Equity | I18227: =_xlfn.XLOOKUP(tbl_GL[[#This Row],[Account_key]],tbl_COA[Account_key],tbl_COA[SubClass2],"Not Found") -> Retained Earnings | J18227: =_xlfn.XLOOKUP(tbl_GL[[#This Row],[Account_key]],tbl_COA[Account_key],tbl_COA[SubAccount],,0) -> Retained Earnings | K18227: =YEAR(tbl_GL[[#This Row],[Date]]) -> 2018
A18228: 709.1 | B18228: 43496 | C18228: =C18227 -> 1 | D18228: 200 | E18228: Transfer of Net Profit to Retained Earnings | F18228: 16081 | G18228: =_xlfn.XLOOKUP(tbl_GL[[#This Row],[Account_key]],tbl_COA[Account_key],tbl_COA[Class],"Not Found") -> Liabilities and Owners Equity | H18228: =_xlfn.XLOOKUP(tbl_GL[[#This Row],[Account_key]],tbl_COA[Account_key],tbl_COA[SubClass],"Not Found") -> Owners Equity | I18228: =_xlfn.XLOOKUP(tbl_GL[[#This Row],[Account_key]],tbl_COA[Account_key],tbl_COA[SubClass2],"Not Found") -> Retained Earnings | J18228: =_xlfn.XLOOKUP(tbl_GL[[#This Row],[Account_key]],tbl_COA[Account_key],tbl_COA[SubAccount],,0) -> Retained Earnings | K18228: =YEAR(tbl_GL[[#This Row],[Date]]) -> 2019
... A18239: 1315.1 | B18239: 43830 | C18239: =C18238 -> 1 | D18239: 200 | E18239: Transfer of Net Profit to Retained Earnings | F18239: 71830 | G18239: =_xlfn.XLOOKUP(tbl_GL[[#This Row],[Account_key]],tbl_COA[Account_key],tbl_COA[Class],"Not Found") -> Liabilities and Owners Equity | H18239: =_xlfn.XLOOKUP(tbl_GL[[#This Row],[Account_key]],tbl_COA[Account_key],tbl_COA[SubClass],"Not Found") -> Owners Equity | I18239: =_xlfn.XLOOKUP(tbl_GL[[#This Row],[Account_key]],tbl_COA[Account_key],tbl_COA[SubClass2],"Not Found") -> Retained Earnings | J18239: =_xlfn.XLOOKUP(tbl_GL[[#This Row],[Account_key]],tbl_COA[Account_key],tbl_COA[SubAccount],,0) -> Retained Earnings | K18239: =YEAR(tbl_GL[[#This Row],[Date]]) -> 2019
A18240: 49.1 | B18240: 43131 | C18240: 2 | D18240: 200 | E18240: Transfer of Net Profit to Retained Earnings | F18240: 1954 | G18240: =_xlfn.XLOOKUP(tbl_GL[[#This Row],[Account_key]],tbl_COA[Account_key],tbl_COA[Class],"Not Found") -> Liabilities and Owners Equity | H18240: =_xlfn.XLOOKUP(tbl_GL[[#This Row],[Account_key]],tbl_COA[Account_key],tbl_COA[SubClass],"Not Found") -> Owners Equity | I18240: =_xlfn.XLOOKUP(tbl_GL[[#This Row],[Account_key]],tbl_COA[Account_key],tbl_COA[SubClass2],"Not Found") -> Retained Earnings | J18240: =_xlfn.XLOOKUP(tbl_GL[[#This Row],[Account_key]],tbl_COA[Account_key],tbl_COA[SubAccount],,0) -> Retained Earnings | K18240: =YEAR(tbl_GL[[#This Row],[Date]]) -> 2018
A18241: 93.1 | B18241: 43159 | C18241: =C18240 -> 2 | D18241: 200 | E18241: Transfer of Net Profit to Retained Earnings | F18241: -1593 | G18241: =_xlfn.XLOOKUP(tbl_GL[[#This Row],[Account_key]],tbl_COA[Account_key],tbl_COA[Class],"Not Found") -> Liabilities and Owners Equity | H18241: =_xlfn.XLOOKUP(tbl_GL[[#This Row],[Account_key]],tbl_COA[Account_key],tbl_COA[SubClass],"Not Found") -> Owners Equity | I18241: =_xlfn.XLOOKUP(tbl_GL[[#This Row],[Account_key]],tbl_COA[Account_key],tbl_COA[SubClass2],"Not Found") -> Retained Earnings | J18241: =_xlfn.XLOOKUP(tbl_GL[[#This Row],[Account_key]],tbl_COA[Account_key],tbl_COA[SubAccount],,0) -> Retained Earnings | K18241: =YEAR(tbl_GL[[#This Row],[Date]]) -> 2018
A18242: 142.1 | B18242: 43190 | C18242: =C18241 -> 2 | D18242: 200 | E18242: Transfer of Net Profit to Retained Earnings | F18242: -729 | G18242: =_xlfn.XLOOKUP(tbl_GL[[#This Row],[Account_key]],tbl_COA[Account_key],tbl_COA[Class],"Not Found") -> Liabilities and Owners Equity | H18242: =_xlfn.XLOOKUP(tbl_GL[[#This Row],[Account_key]],tbl_COA[Account_key],tbl_COA[SubClass],"Not Found") -> Owners Equity | I18242: =_xlfn.XLOOKUP(tbl_GL[[#This Row],[Account_key]],tbl_COA[Account_key],tbl_COA[SubClass2],"Not Found") -> Retained Earnings | J18242: =_xlfn.XLOOKUP(tbl_GL[[#This Row],[Account_key]],tbl_COA[Account_key],tbl_COA[SubAccount],,0) -> Retained Earnings | K18242: =YEAR(tbl_GL[[#This Row],[Date]]) -> 2018
A18243: 200.1 | B18243: 43220 | C18243: =C18242 -> 2 | D18243: 200 | E18243: Transfer of Net Profit to Retained Earnings | F18243: 2798 | G18243: =_xlfn.XLOOKUP(tbl_GL[[#This Row],[Account_key]],tbl_COA[Account_key],tbl_COA[Class],"Not Found") -> Liabilities and Owners Equity | H18243: =_xlfn.XLOOKUP(tbl_GL[[#This Row],[Account_key]],tbl_COA[Account_key],tbl_COA[SubClass],"Not Found") -> Owners Equity | I18243: =_xlfn.XLOOKUP(tbl_GL[[#This Row],[Account_key]],tbl_COA[Account_key],tbl_COA[SubClass2],"Not Found") -> Retained Earnings | J18243: =_xlfn.XLOOKUP(tbl_GL[[#This Row],[Account_key]],tbl_COA[Account_key],tbl_COA[SubAccount],,0) -> Retained Earnings | K18243: =YEAR(tbl_GL[[#This Row],[Date]]) -> 2018
A18244: 250.1 | B18244: 43251 | C18244: =C18243 -> 2 | D18244: 200 | E18244: Transfer of Net Profit to Retained Earnings | F18244: 1633 | G18244: =_xlfn.XLOOKUP(tbl_GL[[#This Row],[Account_key]],tbl_COA[Account_key],tbl_COA[Class],"Not Found") -> Liabilities and Owners Equity | H18244: =_xlfn.XLOOKUP(tbl_GL[[#This Row],[Account_key]],tbl_COA[Account_key],tbl_COA[SubClass],"Not Found") -> Owners Equity | I18244: =_xlfn.XLOOKUP(tbl_GL[[#This Row],[Account_key]],tbl_COA[Account_key],tbl_COA[SubClass2],"Not Found") -> Retained Earnings | J18244: =_xlfn.XLOOKUP(tbl_GL[[#This Row],[Account_key]],tbl_COA[Account_key],tbl_COA[SubAccount],,0) -> Retained Earnings | K18244: =YEAR(tbl_GL[[#This Row],[Date]]) -> 2018
A18245: 301.1 | B18245: 43281 | C18245: =C18244 -> 2 | D18245: 200 | E18245: Transfer of Net Profit to Retained Earnings | F18245: 1791 | G18245: =_xlfn.XLOOKUP(tbl_GL[[#This Row],[Account_key]],tbl_COA[Account_key],tbl_COA[Class],"Not Found") -> Liabilities and Owners Equity | H18245: =_xlfn.XLOOKUP(tbl_GL[[#This Row],[Account_key]],tbl_COA[Account_key],tbl_COA[SubClass],"Not Found") -> Owners Equity | I18245: =_xlfn.XLOOKUP(tbl_GL[[#This Row],[Account_key]],tbl_COA[Account_key],tbl_COA[SubClass2],"Not Found") -> Retained Earnings | J18245: =_xlfn.XLOOKUP(tbl_GL[[#This Row],[Account_key]],tbl_COA[Account_key],tbl_COA[SubAccount],,0) -> Retained Earnings | K18245: =YEAR(tbl_GL[[#This Row],[Date]]) -> 2018
A18246: 363.1 | B18246: 43312 | C18246: =C18245 -> 2 | D18246: 200 | E18246: Transfer of Net Profit to Retained Earnings | F18246: 8365 | G18246: =_xlfn.XLOOKUP(tbl_GL[[#This Row],[Account_key]],tbl_COA[Account_key],tbl_COA[Class],"Not Found") -> Liabilities and Owners Equity | H18246: =_xlfn.XLOOKUP(tbl_GL[[#This Row],[Account_key]],tbl_COA[Account_key],tbl_COA[SubClass],"Not Found") -> Owners Equity | I18246: =_xlfn.XLOOKUP(tbl_GL[[#This Row],[Account_key]],tbl_COA[Account_key],tbl_COA[SubClass2],"Not Found") -> Retained Earnings | J18246: =_xlfn.XLOOKUP(tbl_GL[[#This Row],[Account_key]],tbl_COA[Account_key],tbl_COA[SubAccount],,0) -> Retained Earnings | K18246: =YEAR(tbl_GL[[#This Row],[Date]]) -> 2018
A18247: 422.1 | B18247: 43343 | C18247: =C18246 -> 2 | D18247: 200 | E18247: Transfer of Net Profit to Retained Earnings | F18247: 7792 | G18247: =_xlfn.XLOOKUP(tbl_GL[[#This Row],[Account_key]],tbl_COA[Account_key],tbl_COA[Class],"Not Found") -> Liabilities and Owners Equity | H18247: =_xlfn.XLOOKUP(tbl_GL[[#This Row],[Account_key]],tbl_COA[Account_key],tbl_COA[SubClass],"Not Found") -> Owners Equity | I18247: =_xlfn.XLOOKUP(tbl_GL[[#This Row],[Account_key]],tbl_COA[Account_key],tbl_COA[SubClass2],"Not Found") -> Retained Earnings | J18247: =_xlfn.XLOOKUP(tbl_GL[[#This Row],[Account_key]],tbl_COA[Account_key],tbl_COA[SubAccount],,0) -> Retained Earnings | K18247: =YEAR(tbl_GL[[#This Row],[Date]]) -> 2018
A18248: 478.1 | B18248: 43373 | C18248: =C18247 -> 2 | D18248: 200 | E18248: Transfer of Net Profit to Retained Earnings | F18248: 6850 | G18248: =_xlfn.XLOOKUP(tbl_GL[[#This Row],[Account_key]],tbl_COA[Account_key],tbl_COA[Class],"Not Found") -> Liabilities and Owners Equity | H18248: =_xlfn.XLOOKUP(tbl_GL[[#This Row],[Account_key]],tbl_COA[Account_key],tbl_COA[SubClass],"Not Found") -> Owners Equity | I18248: =_xlfn.XLOOKUP(tbl_GL[[#This Row],[Account_key]],tbl_COA[Account_key],tbl_COA[SubClass2],"Not Found") -> Retained Earnings | J18248: =_xlfn.XLOOKUP(tbl_GL[[#This Row],[Account_key]],tbl_COA[Account_key],tbl_COA[SubAccount],,0) -> Retained Earnings | K18248: =YEAR(tbl_GL[[#This Row],[Date]]) -> 2018
A18249: 539.1 | B18249: 43404 | C18249: =C18248 -> 2 | D18249: 200 | E18249: Transfer of Net Profit to Retained Earnings | F18249: 9252 | G18249: =_xlfn.XLOOKUP(tbl_GL[[#This Row],[Account_key]],tbl_COA[Account_key],tbl_COA[Class],"Not Found") -> Liabilities and Owners Equity | H18249: =_xlfn.XLOOKUP(tbl_GL[[#This Row],[Account_key]],tbl_COA[Account_key],tbl_COA[SubClass],"Not Found") -> Owners Equity | I18249: =_xlfn.XLOOKUP(tbl_GL[[#This Row],[Account_key]],tbl_COA[Account_key],tbl_COA[SubClass2],"Not Found") -> Retained Earnings | J18249: =_xlfn.XLOOKUP(tbl_GL[[#This Row],[Account_key]],tbl_COA[Account_key],tbl_COA[SubAccount],,0) -> Retained Earnings | K18249: =YEAR(tbl_GL[[#This Row],[Date]]) -> 2018
A18250: 601.1 | B18250: 43434 | C18250: =C18249 -> 2 | D18250: 200 | E18250: Transfer of Net Profit to Retained Earnings | F18250: 16914 | G18250: =_xlfn.XLOOKUP(tbl_GL[[#This Row],[Account_key]],tbl_COA[Account_key],tbl_COA[Class],"Not Found") -> Liabilities and Owners Equity | H18250: =_xlfn.XLOOKUP(tbl_GL[[#This Row],[Account_key]],tbl_COA[Account_key],tbl_COA[SubClass],"Not Found") -> Owners Equity | I18250: =_xlfn.XLOOKUP(tbl_GL[[#This Row],[Account_key]],tbl_COA[Account_key],tbl_COA[SubClass2],"Not Found") -> Retained Earnings | J18250: =_xlfn.XLOOKUP(tbl_GL[[#This Row],[Account_key]],tbl_COA[Account_key],tbl_COA[SubAccount],,0) -> Retained Earnings | K18250: =YEAR(tbl_GL[[#This Row],[Date]]) -> 2018
A18251: 654.1 | B18251: 43465 | C18251: =C18250 -> 2 | D18251: 200 | E18251: Transfer of Net Profit to Retained Earnings | F18251: 12510 | G18251: =_xlfn.XLOOKUP(tbl_GL[[#This Row],[Account_key]],tbl_COA[Account_key],tbl_COA[Class],"Not Found") -> Liabilities and Owners Equity | H18251: =_xlfn.XLOOKUP(tbl_GL[[#This Row],[Account_key]],tbl_COA[Account_key],tbl_COA[SubClass],"Not Found") -> Owners Equity | I18251: =_xlfn.XLOOKUP(tbl_GL[[#This Row],[Account_key]],tbl_COA[Account_key],tbl_COA[SubClass2],"Not Found") -> Retained Earnings | J18251: =_xlfn.XLOOKUP(tbl_GL[[#This Row],[Account_key]],tbl_COA[Account_key],tbl_COA[SubAccount],,0) -> Retained Earnings | K18251: =YEAR(tbl_GL[[#This Row],[Date]]) -> 2018
A18252: 717.1 | B18252: 43496 | C18252: =C18251 -> 2 | D18252: 200 | E18252: Transfer of Net Profit to Retained Earnings | F18252: 4021 | G18252: =_xlfn.XLOOKUP(tbl_GL[[#This Row],[Account_key]],tbl_COA[Account_key],tbl_COA[Class],"Not Found") -> Liabilities and Owners Equity | H18252: =_xlfn.XLOOKUP(tbl_GL[[#This Row],[Account_key]],tbl_COA[Account_key],tbl_COA[SubClass],"Not Found") -> Owners Equity | I18252: =_xlfn.XLOOKUP(tbl_GL[[#This Row],[Account_key]],tbl_COA[Account_key],tbl_COA[SubClass2],"Not Found") -> Retained Earnings | J18252: =_xlfn.XLOOKUP(tbl_GL[[#This Row],[Account_key]],tbl_COA[Account_key],tbl_COA[SubAccount],,0) -> Retained Earnings | K18252: =YEAR(tbl_GL[[#This Row],[Date]]) -> 2019
...

Sheet P&L_2018 & 2019
B1: Income Statement | E1: Variance Analysis
C2: 2018 | D2: =C2+1 -> 2019 | E2: Absolute Variance | F2: Variance % | G2: Remarks & Insights
B3: Sales | C3: =SUMIFS(tbl_GL[Amount],tbl_GL[SubClass],'P&L_2018 & 2019'!$B3,tbl_GL[Year],'P&L_2018 & 2019'!$C$2) -> 3575428 | D3: =SUMIFS(tbl_GL[Amount],tbl_GL[SubClass],'P&L_2018 & 2019'!B3,tbl_GL[Year],'P&L_2018 & 2019'!$D$2) -> 5697845 | E3: =D3-C3 -> 2122417 | F3: =E3/C3 -> 0.59361201 | G3: Primary growth driver. Exceptional increase fueled by new business acquisitions and market expansion
B4: Sales Growth | C4: 0 | D4: =D3/C3-1 -> 0.59361201
B6: Cost of Sales | C6: =SUMIFS(tbl_GL[Amount],tbl_GL[SubClass],'P&L_2018 & 2019'!$B6,tbl_GL[Year],'P&L_2018 & 2019'!$C$2) -> -1192182 | D6: =SUMIFS(tbl_GL[Amount],tbl_GL[SubClass],'P&L_2018 & 2019'!B6,tbl_GL[Year],'P&L_2018 & 2019'!$D$2) -> -1729299 | E6: =D6-C6 -> -537117 | F6: =E6/C6 -> 0.45053272 | G6: Increased in line with higher sales volume but at a slower rate than revenue, indicating improved purchasing efficiency or economies of scale
B7: COGS % Sales | C7: =C6/C3*-1 -> 0.33343756 | D7: =D6/D3*-1 -> 0.30350053
B9: Gross Profit | C9: =SUM(C3:C6) -> 2383246 | D9: =SUM(D3:D6) -> 3968546.6 | E9: =D9-C9 -> 1585300.6 | F9: =E9/C9 -> 0.66518546 | G9: Strong performance. Gross Margin expanded from 67% to 70%, meaning a greater portion of each sales rupee is retained as gross profit.
B10: Gross Margin % Sales | C10: =C9/C3 -> 0.66656244 | D10: =D9/D3 -> 0.69649957
B13: Operating Expenses | C13: =SUMIFS(tbl_GL[Amount],tbl_GL[SubClass],'P&L_2018 & 2019'!$B13,tbl_GL[Year],'P&L_2018 & 2019'!$C$2) -> -1235441 | D13: =SUMIFS(tbl_GL[Amount],tbl_GL[SubClass],'P&L_2018 & 2019'!B13,tbl_GL[Year],'P&L_2018 & 2019'!$D$2) -> -1960802 | E13: =D13-C13 -> -725361 | F13: =E13/C13 -> 0.58712719 | G13: Increased nearly in line with sales (59% vs. 58.7%). Opex as a % of sales improved slightly from 35% to 34%, showing reasonable control during a high-growth phase.
B14: Opex % Sales | C14: =C13/C3*-1 -> 0.34553653 | D14: =D13/D3*-1 -> 0.34413046
B16: EBITDA | C16: =SUM(C9:C13) -> 1147805.7 | D16: =SUM(D9:D13) -> 2007745.3 | E16: =D16-C16 -> 859939.62 | F16: =E16/C16 -> 0.74920315 | G16: Outstanding operational performance. EBITDA grew faster than sales, leading to a margin expansion from 32% to 35%. This indicates strong leverage from the operating model.
B17: EBITDA % Sales | C17: =C16/C3 -> 0.32102609 | D17: =D16/D3 -> 0.35236924
B18: EBITDA % Growth | C18: 0 | D18: =D16/C16-1 -> 0.74920315
B20: Depreciation & Amortization | C20: =SUMIFS(tbl_GL[Amount],tbl_GL[SubClass],'P&L_2018 & 2019'!$B20,tbl_GL[Year],'P&L_2018 & 2019'!$C$2) -> -407004 | D20: =SUMIFS(tbl_GL[Amount],tbl_GL[SubClass],'P&L_2018 & 2019'!B20,tbl_GL[Year],'P&L_2018 & 2019'!$D$2) -> -532056 | E20: =D20-C20 -> -125052 | F20: =E20/C20 -> 0.30725005 | G20: Increased due to capital expenditures on new fixed and intangible assets, supporting the recent expansion.
B21: D&A % Sales | C21: =C20/C3*-1 -> 0.11383364 | D21: =D20/D3*-1 -> 0.093378462
B23: Non-operating | C23: =SUMIFS(tbl_GL[Amount],tbl_GL[Catagorization],'P&L_2018 & 2019'!$B23,tbl_GL[Year],'P&L_2018 & 2019'!$C$2) -> 36477 | D23: =SUMIFS(tbl_GL[Amount],tbl_GL[Catagorization],'P&L_2018 & 2019'!$B23,tbl_GL[Year],'P&L_2018 & 2019'!$D$2) -> 47162 | E23: =D23-C23 -> 10685 | F23: =E23/C23 -> 0.29292431
B25: EBIT | C25: =SUM(C16:C23) -> 777279.1 | D25: =SUM(D16:D23) -> 1522852.5 | E25: =D25-C25 -> 745573.38 | F25: =E25/C25 -> 0.95920935 | G25: Profit nearly doubled. EBIT margin saw a significant jump from 22% to 27%, reflecting excellent control over the core business profitability after accounting for asset base growth.
B26: EBIT % Sales | C26: =C25/C3 -> 0.2173947 | D26: =D25/D3 -> 0.26726815
B28: Interest & Tax | C28: =SUMIFS(tbl_GL[Amount],tbl_GL[Catagorization],'P&L_2018 & 2019'!$B28,tbl_GL[Year],'P&L_2018 & 2019'!$C$2) -> -153422 | D28: =SUMIFS(tbl_GL[Amount],tbl_GL[Catagorization],'P&L_2018 & 2019'!$B28,tbl_GL[Year],'P&L_2018 & 2019'!$D$2) -> -219703 | E28: =D28-C28 -> -66281 | F28: =E28/C28 -> 0.43201757 | G28: Increased due to higher debt levels (for expansion) and a larger pre-tax profit base. Well-controlled relative to profit growth
B29: Interest & Tax % Sales | C29: =C28/C3*-1 -> 0.042910108 | D29: =D28/D3*-1 -> 0.038558964
B31: Net profit | C31: =SUM(C25:C28) -> 623857.32 | D31: =SUM(D25:D28) -> 1303149.8 | E31: =D31-C31 -> 679292.43 | F31: =E31/C31 -> 1.0888586 | G31: Remarkable bottom-line growth. Net Profit margin improved substantially from 17% to 23%, demonstrating that growth is highly profitable and efficiently managed.
B32: Net Margins | C32: =C31/C3 -> 0.17448465 | D32: =D31/D3 -> 0.22870923

Sheet BalanceSheet_2018_2019
A2: # | B2: BalanceSheet For FY2018 to FY2019
B3: Category | C3: Balance Sheet | D3: 2018 | E3: 2019
B4: Current Assets | C4: Cash at Bank | D4: =SUMIFS(tbl_GL[Amount],tbl_GL[Account],BalanceSheet_2018_2019!$C$4,tbl_GL[Year],BalanceSheet_2018_2019!$D$3) -> 2056505 | E4: =SUMIFS(tbl_GL[Amount],tbl_GL[Account],BalanceSheet_2018_2019!$C$4,tbl_GL[Year],BalanceSheet_2018_2019!$E$3) -> 2839487
C5: Cash in hand | D5: =SUMIFS(tbl_GL[Amount],tbl_GL[Account],BalanceSheet_2018_2019!$C5,tbl_GL[Year],BalanceSheet_2018_2019!$D$3) -> 51186 | E5: =SUMIFS(tbl_GL[Amount],tbl_GL[Account],BalanceSheet_2018_2019!$C5,tbl_GL[Year],BalanceSheet_2018_2019!$E$3) -> 163836
C6: Trade Receivables | D6: =SUMIFS(tbl_GL[Amount],tbl_GL[Account],BalanceSheet_2018_2019!$C6,tbl_GL[Year],BalanceSheet_2018_2019!$D$3) -> 551614 | E6: =SUMIFS(tbl_GL[Amount],tbl_GL[Account],BalanceSheet_2018_2019!$C6,tbl_GL[Year],BalanceSheet_2018_2019!$E$3) -> 228848
C7: Inventory | D7: =SUMIFS(tbl_GL[Amount],tbl_GL[Account],BalanceSheet_2018_2019!$C7,tbl_GL[Year],BalanceSheet_2018_2019!$D$3) -> 105834 | E7: =SUMIFS(tbl_GL[Amount],tbl_GL[Account],BalanceSheet_2018_2019!$C7,tbl_GL[Year],BalanceSheet_2018_2019!$E$3) -> 416529
C8: Securities | D8: =SUMIFS(tbl_GL[Amount],tbl_GL[Account],BalanceSheet_2018_2019!$C8,tbl_GL[Year],BalanceSheet_2018_2019!$D$3) -> 258667 | E8: =SUMIFS(tbl_GL[Amount],tbl_GL[Account],BalanceSheet_2018_2019!$C8,tbl_GL[Year],BalanceSheet_2018_2019!$E$3) -> 384000
B9: Total Current Assets | D9: =SUM(D4:D9) -> 3023806 | E9: =SUM(E4:E9) -> 4032700
B10: Non-Current Assets | C10: Office Furniture & Equipment | D10: =SUMIFS(tbl_GL[Amount],tbl_GL[Account],BalanceSheet_2018_2019!$C10,tbl_GL[Year],BalanceSheet_2018_2019!$D$3) -> 776004 | E10: =SUMIFS(tbl_GL[Amount],tbl_GL[Account],BalanceSheet_2018_2019!$C10,tbl_GL[Year],BalanceSheet_2018_2019!$E$3) -> 1252800
C11: Patents and Trademarks | D11: =SUMIFS(tbl_GL[Amount],tbl_GL[Account],BalanceSheet_2018_2019!$C11,tbl_GL[Year],BalanceSheet_2018_2019!$D$3) -> 75992 | E11: =SUMIFS(tbl_GL[Amount],tbl_GL[Account],BalanceSheet_2018_2019!$C11,tbl_GL[Year],BalanceSheet_2018_2019!$E$3) -> 76794
B12: Total Non-Current Assets | D12: =SUM(D10:D12) -> 851996 | E12: =SUM(E10:E12) -> 1329594
B13: Total Assets | D13: =D9+D12 -> 3875802 | E13: =E9+E12 -> 5362294
B14: Current Liabilities | C14: Trade Payables | D14: =SUMIFS(tbl_GL[Amount],tbl_GL[Account],BalanceSheet_2018_2019!$C14,tbl_GL[Year],BalanceSheet_2018_2019!$D$3) -> 137668 | E14: =SUMIFS(tbl_GL[Amount],tbl_GL[Account],BalanceSheet_2018_2019!$C14,tbl_GL[Year],BalanceSheet_2018_2019!$E$3) -> 101150
C15: Accrued Expenses | D15: =SUMIFS(tbl_GL[Amount],tbl_GL[Account],BalanceSheet_2018_2019!$C15,tbl_GL[Year],BalanceSheet_2018_2019!$D$3) -> 146709 | E15: =SUMIFS(tbl_GL[Amount],tbl_GL[Account],BalanceSheet_2018_2019!$C15,tbl_GL[Year],BalanceSheet_2018_2019!$E$3) -> 78716
C16: Interest Payable | D16: =SUMIFS(tbl_GL[Amount],tbl_GL[Account],BalanceSheet_2018_2019!$C16,tbl_GL[Year],BalanceSheet_2018_2019!$D$3) -> 1320 | E16: =SUMIFS(tbl_GL[Amount],tbl_GL[Account],BalanceSheet_2018_2019!$C16,tbl_GL[Year],BalanceSheet_2018_2019!$E$3) -> 600
C17: Tax Payable | D17: =SUMIFS(tbl_GL[Amount],tbl_GL[Account],BalanceSheet_2018_2019!$C17,tbl_GL[Year],BalanceSheet_2018_2019!$D$3) -> 137582 | E17: =SUMIFS(tbl_GL[Amount],tbl_GL[Account],BalanceSheet_2018_2019!$C17,tbl_GL[Year],BalanceSheet_2018_2019!$E$3) -> 60531
C18: Dividends Payable | D18: =SUMIFS(tbl_GL[Amount],tbl_GL[Account],BalanceSheet_2018_2019!$C18,tbl_GL[Year],BalanceSheet_2018_2019!$D$3) -> 161667 | E18: =SUMIFS(tbl_GL[Amount],tbl_GL[Account],BalanceSheet_2018_2019!$C18,tbl_GL[Year],BalanceSheet_2018_2019!$E$3) -> 34450
B19: Total Current Liabilities | D19: =SUM(D14:D18) -> 584946 | E19: =SUM(E14:E18) -> 275447
B20: Non-Current Liabilities | C20: Long Term Obligations | D20: =SUMIFS(tbl_GL[Amount],tbl_GL[Account],BalanceSheet_2018_2019!$C20,tbl_GL[Year],BalanceSheet_2018_2019!$D$3) -> 260000 | E20: =SUMIFS(tbl_GL[Amount],tbl_GL[Account],BalanceSheet_2018_2019!$C20,tbl_GL[Year],BalanceSheet_2018_2019!$E$3) -> 307500
B21: Total Non-Current Liabilities | D21: =SUM(D20) -> 260000 | E21: =SUM(E20) -> 307500
B22: Owner’s Equity | C22: Share Capital | D22: =SUMIFS(tbl_GL[Amount],tbl_GL[Account],BalanceSheet_2018_2019!$C22,tbl_GL[Year],BalanceSheet_2018_2019!$D$3) -> 2666667 | E22: =SUMIFS(tbl_GL[Amount],tbl_GL[Account],BalanceSheet_2018_2019!$C22,tbl_GL[Year],BalanceSheet_2018_2019!$E$3) -> 3796000
C23: Retained Earnings | D23: =IFERROR('P&L_2018 & 2019'!C31,0) -> 623857.32 | E23: =IFERROR('P&L_2018 & 2019'!D31,0) -> 1303149.8
C24: Dividends Paid | D24: =SUMIFS(tbl_GL[Amount],tbl_GL[Account],BalanceSheet_2018_2019!$C24,tbl_GL[Year],BalanceSheet_2018_2019!$D$3) -> -259667 | E24: =SUMIFS(tbl_GL[Amount],tbl_GL[Account],BalanceSheet_2018_2019!$C24,tbl_GL[Year],BalanceSheet_2018_2019!$E$3) -> -319800
B25: Total Owner’s Equity | D25: =SUM(D22:D25) -> 3030856 | E25: =SUM(E22:E25) -> 4779347
B26: Total Liabilities | D26: =D19+D21+D25 -> 3875802 | E26: =E19+E21+E25 -> 5362294
B28: Check | D28: =D13-D26 -> 0 | E28: =E13-E26 -> 0

Sheet CashFlow Bridge
B1: Cash Flow Bridge_FY 2019
B2: LineItem | C2: ='P&L_2018 & 2019'!D2 -> 2019 | D2: Source
B3: Beginning/Starting Cash | C3: =BalanceSheet_2018_2019!D4 -> 2056505 | D3: Cash at Bank in FY2018
B4: Add: Net Profit | C4: ='P&L_2018 & 2019'!D31 -> 1303149.8 | D4: From income statement
B5: Add: Depriciation &Amortization | C5: =-'P&L_2018 & 2019'!D20 -> 532056 | D5: Non-cash expense added back
B6: Add/Less: Working Capital Changes | C6: =WC_Calculation!C6 -> -24447 | D6: Net outflow from AR, Inventory, AP
B7: Less: Capex | C7: =BalanceSheet_2018_2019!D10-BalanceSheet_2018_2019!E10 -> -476796 | D7: Asset purchases (Office Furniture & Equipment)
B8: Less: Dividends Paid | C8: =BalanceSheet_2018_2019!E24 -> -319800 | D8: Cash paid to shareholders
B9: Reconciling Adjustment | C9: -231181 | D9: Other cash movements (e.g., tax, interest, rounding)
B10: Ending Cash Balance | C10: =SUM(C3:C9) -> 2839486.8

Sheet Ratios & Insights
B2: Ratio | C2: 2018 | D2: 2019 | E2: Commentory
B3: Profitability Ratios
B4: Gross Margin % | C4: ='P&L_2018 & 2019'!C9/'P&L_2018 & 2019'!C3 -> 0.66656244 | D4: ='P&L_2018 & 2019'!D9/'P&L_2018 & 2019'!D3 -> 0.69649957 | E4: Gross Margin increased from 66.7% to 69.6%, indicating improved cost control or pricing power.
B5: EBITDA Margin % | C5: ='P&L_2018 & 2019'!C16/'P&L_2018 & 2019'!C3 -> 0.32102609 | D5: ='P&L_2018 & 2019'!D16/'P&L_2018 & 2019'!D3 -> 0.35236924 | E5: EBITDA Margin rose from 32.1% to 35.2%, reflecting better operating leverage and disciplined expense management.
B6: Net Profit Margin % | C6: ='P&L_2018 & 2019'!C31/'P&L_2018 & 2019'!C3 -> 0.17448465 | D6: ='P&L_2018 & 2019'!D31/'P&L_2018 & 2019'!D3 -> 0.22870923 | E6: Net Profit Margin jumped from 17.4% to 22.9%, showing enhanced bottom-line performance, possibly due to lower interest/tax burden or improved non-operating income.
B7: Liquidity Ratios
B8: Current Ratio | C8: =BalanceSheet_2018_2019!D9/BalanceSheet_2018_2019!D19 -> 5.1693763 | D8: =BalanceSheet_2018_2019!E9/BalanceSheet_2018_2019!E19 -> 14.640566 | E8: Current Ratio surged from 5.17 to 14.64, indicating a significant increase in short-term asset coverage.
B9: Cash Ratio | C9: =(BalanceSheet_2018_2019!D4+BalanceSheet_2018_2019!D5)/BalanceSheet_2018_2019!D19 -> 3.6032232 | D9: =(BalanceSheet_2018_2019!E4+BalanceSheet_2018_2019!E5)/BalanceSheet_2018_2019!E19 -> 10.903451 | E9: Cash Ratio from 3.60 to 10.90, indicating a significant increase in short-term asset coverage.
B10: Leverage Ratio
B11: Debt to Equity | C11: =(BalanceSheet_2018_2019!D19+BalanceSheet_2018_2019!D21)/BalanceSheet_2018_2019!D25 -> 0.27878131 | D11: =(BalanceSheet_2018_2019!E19+BalanceSheet_2018_2019!E21)/BalanceSheet_2018_2019!E25 -> 0.1219721 | E11: Debt to Equity dropped from 0.28 to 0.12, suggesting reduced reliance on debt financing.

Sheet WC_Calculation
B1: Working Capital_Calculation
B2: Component | C2: Change (₹) | D2: Cash Impact
B3: Trade Receivables | C3: =BalanceSheet_2018_2019!D6-BalanceSheet_2018_2019!E6 -> 322766 | D3: Cash Inflow
B4: Inventory | C4: =BalanceSheet_2018_2019!D7-BalanceSheet_2018_2019!E7 -> -310695 | D4: Cash Outflow
B5: Trade Payables | C5: =BalanceSheet_2018_2019!D14-BalanceSheet_2018_2019!E14 -> 36518 | D5: Cash Outflow
C6: =C3+C4-C5 -> -24447

Sheet Forecast_2019
A2: # | B2: Assumptions
B3: Metric | C3: FY2018 Actual | D3: FY2019 Forecast Assumption | E3: Notes
B4: Sales Growth | C4: - | D4: 0.49 | E4: Slight miss on revenue targets
B5: COGS % of Sales | C5: 0.33 | D5: 0.33 | E5: Raw material inflation
B6: Opex % of Sales | C6: 0.35 | D6: 0.35 | E6: Hiring & marketing push
B7: EBITDA Margin | C7: 0.32 | D7: 0.332 | E7: Lower leverage
B8: D&A % of Sales | C8: 0.11 | D8: 0.1 | E8: Stable CAPEX
B9: Interest & Tax % | C9: 0.04 | D9: 0.042 | E9: Slight increase
B10: Net Profit Margin | C10: 0.17 | D10: 0.21 | E10: Moderate dip in profit margin
A12: # | B12: Forecasted P&L For FY 2019
B13: P&L Line Item | C13: FY2018 Actual | D13: FY2019 Forecast
B14: =AOP_2019!B16 -> Sales | C14: =AOP_2019!C16 -> 3575428 | D14: =C14*(1+Forecast_2019!D4) -> 5327387.7
B15: Sales Growth | C15: 0 | D15: =(D14-C14)/C14 -> 0.49
B16: =AOP_2019!B17 -> Cost Of Sales | C16: =AOP_2019!C17 -> -1192182 | D16: =Forecast_2019!D14*Forecast_2019!D5*-1 -> -1758037.9
B17: COGS % Sales | C17: =C16/C14 -> -0.33343756 | D17: =D16/D14 -> -0.33
B18: =AOP_2019!B18 -> Gross Profit | C18: =AOP_2019!C18 -> 2383246 | D18: =SUM(D14:D16) -> 3569350.3
B19: Gross Profit Margin % | C19: =C18/C14 -> 0.66656244 | D19: =D18/D14 -> 0.67000009
B21: =AOP_2019!B21 -> Operating Expenses | C21: =AOP_2019!C21 -> -1235441 | D21: =D14*Forecast_2019!D6*-1 -> -1864585.7
B22: OpEx % Sales | C22: =C21/C14 -> -0.34553653 | D22: =D21/D14 -> -0.35
B23: =AOP_2019!B22 -> EBITDA | C23: =AOP_2019!C22 -> 1147805.7 | D23: =SUM(D18:D21) -> 1704765.2
B24: EBITDA % Sales | C24: =C23/C14 -> 0.32102609 | D24: =D23/D14 -> 0.32000022
B26: =AOP_2019!B25 -> Depreciation & Amortization | C26: =AOP_2019!C25 -> -407004 | D26: =C26*(1+Forecast_2019!D8) -> -447704.4
B27: =AOP_2019!B26 -> Non-Operating | C27: =AOP_2019!C26 -> 36477 | D27: 45596.25
B28: =AOP_2019!B27 -> Interest & Tax | C28: =AOP_2019!C27 -> -153422 | D28: =C28*(1+Forecast_2019!D9) -> -159865.72
B29: =AOP_2019!B28 -> Net Profit | C29: =AOP_2019!C28 -> 623856.99 | D29: =SUM(D23:D28) -> 1142791.7
B30: Net Profit % Sales | C30: =C29/C14 -> 0.17448456 | D30: =D29/D14 -> 0.21451258

Sheet AOP_2019
A2: # | B2: Assumptions
B3: Metric | C3: FY2018 Actual | D3: FY2019 AOP Assumption | E3: Rationale / Business Logic
B4: Revenue Growth | C4: 3575428 | D4: 0.55 | E4: Aggressive top-line growth expected from new client wins and market expansion.
B5: COGS (% of Sales) | C5: 0.33 | D5: 0.31 | E5: Improved efficiency and supplier negotiations reduce cost ratio slightly.
B6: Opex (% of Sales) | C6: 0.35 | D6: 0.34 | E6: Tighter cost control; moderate rise due to scaling.
B7: Gross Margin % | C7: 0.67 | D7: 0.69 | E7: Efficiency improvement due to higher volumes.
B8: EBITDA Growth | C8: 1147806 | D8: 0.65 | E8: Revenue scaling with controlled cost expansion.
B9: Depreciation & Amortization | C9: 407004 | D9: 0.3 | E9: Increased due to CAPEX for capacity and systems.
B10: Non-operating Income | C10: 36477 | D10: 0.25 | E10: Small increase from investments or interest income.
B11: Interest & Tax (% of Sales) | C11: 0.04 | D11: 0.04 | E11: Expected to remain constant.
B12: Net Margin % | C12: 0.17 | D12: 0.22 | E12: Strong improvement planned due to margin expansion.
A14: # | B14: Annual Operating Plan - FY2019
B15: Line Item | C15: FY2018 Actual | D15: FY2019 AOP (Projected) | E15: Growth
B16: Sales | C16: =VLOOKUP(B$16,'P&L_2018 & 2019'!$B3:$D31,2,0) -> 3575428 | D16: =C16*(1+AOP_2019!D4) -> 5541913.4 | E16: =(D16-C16)/C16 -> 0.55
B17: Cost Of Sales | C17: =VLOOKUP(B17,'P&L_2018 & 2019'!B3:D32,2,0) -> -1192182 | D17: =(D16*AOP_2019!D5)*-1 -> -1717993.2 | E17: =(D17-C17)/C17 -> 0.4410494
B18: Gross Profit | C18: =SUM(C16:C17) -> 2383246 | D18: =SUM(D16:D17) -> 3823920.2 | E18: =(D18-C18)/C18 -> 0.60450086
B19: Gross Margin % Sales | C19: =C18/C16 -> 0.66656244 | D19: =D18/D16 -> 0.69 | E19: 0
B21: Operating Expenses | C21: =VLOOKUP(B21,'P&L_2018 & 2019'!B5:D34,2,0) -> -1235441 | D21: =(AOP_2019!D16*AOP_2019!D6)*-1 -> -1884250.6 | E21: =(D21-C21)/C21 -> 0.52516434
B22: EBITDA | C22: =SUM(C18:C21) -> 1147805.7 | D22: =SUM(D18:D21) -> 1939670.4 | E22: =(D22-C22)/C22 -> 0.68989441
B23: EBITDA % Sales | C23: =C22/C16 -> 0.32102609 | D23: =D22/D16 -> 0.35000012 | E23: 0
B25: Depreciation & Amortization | C25: =VLOOKUP(B25,'P&L_2018 & 2019'!B7:D36,2,0) -> -407004 | D25: =C25*(1+AOP_2019!D9) -> -529105.2 | E25: =(D25-C25)/C25 -> 0.3
B26: Non-Operating | C26: =VLOOKUP(B26,'P&L_2018 & 2019'!B8:D37,2,0) -> 36477 | D26: =C26*(1+AOP_2019!D10) -> 45596.25 | E26: =(D26-C26)/C26 -> 0.25
B27: Interest & Tax | C27: =VLOOKUP(B27,'P&L_2018 & 2019'!B9:D38,2,0) -> -153422 | D27: =(D16*AOP_2019!D11)*-1 -> -221676.54 | E27: =(D27-C27)/C27 -> 0.44488102
B28: Net Profit | C28: =SUM(C22:C27) -> 623856.99 | D28: =SUM(D22:D27) -> 1234485.2 | E28: =(D28-C28)/C28 -> 0.97879525
B29: Net Profit Margin % Sales | C29: =C28/C16 -> 0.17448456 | D29: =D28/D16 -> 0.22275434 | E29: 0

Sheet Financials_Combined_2018_2019
B2: P&L Line Item | C2: Category | D2: FY2018 Actual | E2: FY2019 AOP (Plan) | F2: FY2019 Forecast | G2: Δ vs AOP | H2: Δ% | I2: Commentary
B3: =AOP_2019!B16 -> Sales | C3: Revenue | D3: ='P&L_2018 & 2019'!D3 -> 5697845 | E3: =AOP_2019!D16 -> 5541913.4 | F3: =Forecast_2019!D14 -> 5327387.7 | G3: =F3-E3 -> -214525.68 | H3: =(F3-E3)/E3 -> -0.038709677 | I3: Slight revenue dip vs plan due to delayed project closures and moderate demand.
B4: =AOP_2019!B17 -> Cost Of Sales | C4: COGS | D4: =AOP_2019!C17 -> -1192182 | E4: =AOP_2019!D17 -> -1717993.2 | F4: =Forecast_2019!D14*Forecast_2019!D5*-1 -> -1758037.9 | G4: =F4-E4 -> -40044.794 | H4: =(F4-E4)/E4 -> 0.023309053 | I4: Raw material cost inflation and supply delays led to higher-than-planned COGS.
B5: =AOP_2019!B18 -> Gross Profit | C5: Margin | D5: =AOP_2019!C18 -> 2383246 | E5: =AOP_2019!D18 -> 3823920.2 | F5: =SUM(F3:F4) -> 3569349.8 | G5: =F5-E5 -> -254570.47 | H5: =(F5-E5)/E5 -> -0.066573165 | I5: Gross margin compression due to cost pressures and reduced pricing flexibility.
B6: =AOP_2019!B21 -> Operating Expenses | C6: Expense | D6: =AOP_2019!C21 -> -1235441 | E6: =AOP_2019!D21 -> -1884250.6 | F6: =F3*Forecast_2019!D6*-1 -> -1864585.7 | G6: =F6-E6 -> 19664.854 | H6: =(F6-E6)/E6 -> -0.010436433 | I6: Controlled opex through optimization in marketing and administrative costs.
B7: =AOP_2019!B22 -> EBITDA | C7: Margin | D7: =AOP_2019!C22 -> 1147805.7 | E7: =AOP_2019!D22 -> 1939670.4 | F7: =SUM(F5:F6) -> 1704764.1 | G7: =F7-E7 -> -234906.31 | H7: =(F7-E7)/E7 -> -0.1211063 | I7: Operating pressure evident; cost control couldn’t fully offset revenue slowdown.
B8: =AOP_2019!B25 -> Depreciation & Amortization | C8: Expense | D8: =AOP_2019!C25 -> -407004 | E8: =AOP_2019!D25 -> -529105.2 | F8: =D8*(1+Forecast_2019!D8) -> -447704.4 | G8: =F8-E8 -> 81400.8 | H8: =(F8-E8)/E8 -> -0.15384615 | I8: Capex delays reduced depreciation expense below plan.
B9: =AOP_2019!B26 -> Non-Operating | C9: Other | D9: =AOP_2019!C26 -> 36477 | E9: =AOP_2019!D26 -> 45596.25 | F9: 45596.25 | G9: =F9-E9 -> 0 | H9: =(F9-E9)/E9 -> 0 | I9: Other income in line with expectations.
B10: =AOP_2019!B27 -> Interest & Tax | C10: Expense | D10: =AOP_2019!C27 -> -153422 | E10: =AOP_2019!D27 -> -221676.54 | F10: =D10*(1+Forecast_2019!D9) -> -159865.72 | G10: =F10-E10 -> 61810.812 | H10: =(F10-E10)/E10 -> -0.27883335 | I10: Lower interest expense due to early loan repayment and tax optimization.
B11: =AOP_2019!B28 -> Net Profit | C11: Margin | D11: =AOP_2019!C28 -> 623856.99 | E11: =AOP_2019!D28 -> 1234485.2 | F11: =SUM(F7:F10) -> 1142790.2 | G11: =F11-E11 -> -91695.048 | H11: =(F11-E11)/E11 -> -0.074277962 | I11: Bottom-line shortfall driven by revenue softness and slight cost escalation.

Sheet Forecast_2020
B2: P&L Line Item | C2: FY2019 (Actuals) | D2: Ratios (FY2019) | E2: Assumptions (FY2020) | F2: FY2020 (Forecast)
B3: ='P&L_2018 & 2019'!B3 -> Sales | C3: ='P&L_2018 & 2019'!D3 -> 5697845 | D3: - | E3: 0.4 | F3: =C3*(1+E3) -> 7976983
B4: ='P&L_2018 & 2019'!B6 -> Cost of Sales | C4: ='P&L_2018 & 2019'!D6 -> -1729299 | D4: =(C4/C3)*-1 -> 0.30350053 | E4: 0.31 | F4: =(F3*E4)*-1 -> -2472864.7
B5: ='P&L_2018 & 2019'!B9 -> Gross Profit | C5: =SUM(C3:C4) -> 3968546 | D5: =C5/C3 -> 0.69649947 | F5: =SUM(F3:F4) -> 5504118.3
B6: ='P&L_2018 & 2019'!B13 -> Operating Expenses | C6: ='P&L_2018 & 2019'!D13 -> -1960802 | D6: =(C6/C3)*-1 -> 0.34413046 | E6: 0.33 | F6: =($F$3*E6)*-1 -> -2632404.4
B7: ='P&L_2018 & 2019'!B16 -> EBITDA | C7: =SUM(C5:C6) -> 2007744 | D7: =C7/C3 -> 0.35236901 | F7: =SUM(F5:F6) -> 2871713.9
B8: ='P&L_2018 & 2019'!B20 -> Depreciation & Amortization | C8: ='P&L_2018 & 2019'!D20 -> -532056 | D8: =(C8/C3)*-1 -> 0.093378462 | E8: 0.09 | F8: =($F$3*E8)*-1 -> -717928.47
B9: ='P&L_2018 & 2019'!B23 -> Non-operating | C9: ='P&L_2018 & 2019'!D23 -> 47162 | D9: =C9/C3 -> 0.0082771644 | E9: 0.008 | F9: =(F3*E9) -> 63815.864
B10: ='P&L_2018 & 2019'!B25 -> EBIT | C10: =SUM(C7:C9) -> 1522850 | D10: =C10/C3 -> 0.26726771 | F10: =SUM(F7:F9) -> 2217601.3
B11: ='P&L_2018 & 2019'!B28 -> Interest & Tax | C11: ='P&L_2018 & 2019'!D28 -> -219703 | D11: =(C11/C3)*-1 -> 0.038558964 | E11: 0.04 | F11: =($F$3*E11)*-1 -> -319079.32
B12: ='P&L_2018 & 2019'!B31 -> Net profit | C12: =SUM(C10:C11) -> 1303147 | D12: =C12/C3 -> 0.22870875 | F12: =SUM(F10:F11) -> 1898522

Sheet Scenario_2020
B2: Scenario | C2: Worst Case
B4: =Income_Statement_Forecast_Model[[#Headers],[P&L Line Item]] -> P&L Line Item | C4: FY2020 (Forecast)
B5: =Forecast_2020!B3 -> Sales | C5: =IF($C$2="Best Case",Assumptions_Scenarios_2020!F4,IF($C$2="Base Case",Assumptions_Scenarios_2020!F17,Assumptions_Scenarios_2020!F30)) -> 7122306.2
B6: =Forecast_2020!B4 -> Cost of Sales | C6: =IF($C$2="Best Case",Assumptions_Scenarios_2020!F5,IF($C$2="Base Case",Assumptions_Scenarios_2020!F18,Assumptions_Scenarios_2020!F31)) -> -2350361.1
B7: COGS % Sales | C7: =C6/C5 -> -0.33
B9: =Forecast_2020!B5 -> Gross Profit | C9: =SUM(C5:C7) -> 4771944.9
B10: Gross Margin % Sales | C10: =C9/C5 -> 0.66999995
B12: =Forecast_2020!B6 -> Operating Expenses | C12: =IF($C$2="Best Case",Assumptions_Scenarios_2020!F7,IF($C$2="Base Case",Assumptions_Scenarios_2020!F20,Assumptions_Scenarios_2020!F33)) -> -2564030.2
B13: OpEX % Sales | C13: =C12/C5 -> -0.36
B15: =Forecast_2020!B7 -> EBITDA | C15: =SUM(C9:C12) -> 2207915.3
B16: EBITDA % Sales | C16: =C15/C5 -> 0.31000005
B18: =Forecast_2020!B8 -> Depreciation & Amortization | C18: =IF($C$2="Best Case",Assumptions_Scenarios_2020!F9,IF($C$2="Base Case",Assumptions_Scenarios_2020!F22,Assumptions_Scenarios_2020!F35)) -> -676619.09
B19: =Forecast_2020!B9 -> Non-operating | C19: =IF($C$2="Best Case",Assumptions_Scenarios_2020!F10,IF($C$2="Base Case",Assumptions_Scenarios_2020!F23,Assumptions_Scenarios_2020!F36)) -> 35611.531
B21: =Forecast_2020!B10 -> EBIT | C21: =SUM(C15:C19) -> 1566908
B22: EBIT % Sales | C22: =C21/C5 -> 0.22000009
B24: =Forecast_2020!B11 -> Interest & Tax | C24: =IF($C$2="Best Case",Assumptions_Scenarios_2020!F12,IF($C$2="Base Case",Assumptions_Scenarios_2020!F25,Assumptions_Scenarios_2020!F38)) -> -320503.78
B26: =Forecast_2020!B12 -> Net profit | C26: =SUM(C21:C24) -> 1246404.5
B27: Net Margin % Sales | C27: =C26/C5 -> 0.17500012

Sheet Assumptions_Scenarios_2020
A2: # | B2: 1. Best Case(Optimistic Scenario) | C2: Actuals | E2: Forecast
B3: =Income_Statement_Forecast_Model[[#Headers],[P&L Line Item]] -> P&L Line Item | C3: =Income_Statement_Forecast_Model[[#Headers],[FY2019 (Actuals)]] -> FY2019 (Actuals) | D3: =Income_Statement_Forecast_Model[[#Headers],[Ratios (FY2019)]] -> Ratios (FY2019) | E3: =Income_Statement_Forecast_Model[[#Headers],[Assumptions (FY2020)]] -> Assumptions (FY2020) | F3: =Income_Statement_Forecast_Model[[#Headers],[FY2020 (Forecast)]] -> FY2020 (Forecast)
B4: =B17 -> Sales | C4: =C17 -> 5697845 | D4: =D17 -> - | E4: 0.55 | F4: =C4*(1+E4) -> 8831659.8
B5: =B18 -> Cost of Sales | C5: =C18 -> -1729299 | D5: =D18 -> 0.30350053 | E5: 0.29 | F5: =($F$4*E5)*-1 -> -2561181.3
B6: =B19 -> Gross Profit | C6: =C19 -> 3968546 | D6: =D19 -> 0.69649947 | F6: =SUM(F4:F5) -> 6270478.4
B7: =B20 -> Operating Expenses | C7: =C20 -> -1960802 | D7: =D20 -> 0.34413046 | E7: 0.31 | F7: =($F$4*E7)*-1 -> -2737814.5
B8: =B21 -> EBITDA | C8: =C21 -> 2007744 | D8: =D21 -> 0.35236901 | F8: =SUM(F6:F7) -> 3532663.9
B9: =B22 -> Depreciation & Amortization | C9: =C22 -> -532056 | D9: =D22 -> 0.093378462 | E9: 0.085 | F9: =($F$4*E9)*-1 -> -750691.08
B10: =B23 -> Non-operating | C10: =C23 -> 47162 | D10: =D23 -> 0.0082771644 | E10: 0.012 | F10: =($F$4*E10) -> 105979.92
B11: =B24 -> EBIT | C11: =C24 -> 1522850 | D11: =D24 -> 0.26726771 | F11: =SUM(F8:F10) -> 2887952.7
B12: =B25 -> Interest & Tax | C12: =C25 -> -219703 | D12: =D25 -> 0.038558964 | E12: 0.035 | F12: =($F$4*E12)*-1 -> -309108.09
B13: =B26 -> Net profit | C13: =C26 -> 1303147 | D13: =D26 -> 0.22870875 | F13: =SUM(F11:F12) -> 2578844.6
A15: # | B15: 2. Base Case | C15: Actuals | E15: Forecast
B16: =Income_Statement_Forecast_Model[[#Headers],[P&L Line Item]] -> P&L Line Item | C16: =Income_Statement_Forecast_Model[[#Headers],[FY2019 (Actuals)]] -> FY2019 (Actuals) | D16: =Income_Statement_Forecast_Model[[#Headers],[Ratios (FY2019)]] -> Ratios (FY2019) | E16: =Income_Statement_Forecast_Model[[#Headers],[Assumptions (FY2020)]] -> Assumptions (FY2020) | F16: =Income_Statement_Forecast_Model[[#Headers],[FY2020 (Forecast)]] -> FY2020 (Forecast)
B17: =Forecast_2020!B3 -> Sales | C17: =Forecast_2020!C3 -> 5697845 | D17: =Forecast_2020!D3 -> - | E17: =Forecast_2020!E3 -> 0.4 | F17: =Forecast_2020!F3 -> 7976983
B18: =Forecast_2020!B4 -> Cost of Sales | C18: =Forecast_2020!C4 -> -1729299 | D18: =Forecast_2020!D4 -> 0.30350053 | E18: =Forecast_2020!E4 -> 0.31 | F18: =Forecast_2020!F4 -> -2472864.7
B19: =Forecast_2020!B5 -> Gross Profit | C19: =Forecast_2020!C5 -> 3968546 | D19: =Forecast_2020!D5 -> 0.69649947 | F19: =Forecast_2020!F5 -> 5504118.3
B20: =Forecast_2020!B6 -> Operating Expenses | C20: =Forecast_2020!C6 -> -1960802 | D20: =Forecast_2020!D6 -> 0.34413046 | E20: =Forecast_2020!E6 -> 0.33 | F20: =Forecast_2020!F6 -> -2632404.4
B21: =Forecast_2020!B7 -> EBITDA | C21: =Forecast_2020!C7 -> 2007744 | D21: =Forecast_2020!D7 -> 0.35236901 | F21: =Forecast_2020!F7 -> 2871713.9
B22: =Forecast_2020!B8 -> Depreciation & Amortization | C22: =Forecast_2020!C8 -> -532056 | D22: =Forecast_2020!D8 -> 0.093378462 | E22: =Forecast_2020!E8 -> 0.09 | F22: =Forecast_2020!F8 -> -717928.47
B23: =Forecast_2020!B9 -> Non-operating | C23: =Forecast_2020!C9 -> 47162 | D23: =Forecast_2020!D9 -> 0.0082771644 | E23: =Forecast_2020!E9 -> 0.008 | F23: =Forecast_2020!F9 -> 63815.864
B24: =Forecast_2020!B10 -> EBIT | C24: =Forecast_2020!C10 -> 1522850 | D24: =Forecast_2020!D10 -> 0.26726771 | F24: =Forecast_2020!F10 -> 2217601.3
B25: =Forecast_2020!B11 -> Interest & Tax | C25: =Forecast_2020!C11 -> -219703 | D25: =Forecast_2020!D11 -> 0.038558964 | E25: =Forecast_2020!E11 -> 0.04 | F25: =Forecast_2020!F11 -> -319079.32
B26: =Forecast_2020!B12 -> Net profit | C26: =Forecast_2020!C12 -> 1303147 | D26: =Forecast_2020!D12 -> 0.22870875 | F26: =Forecast_2020!F12 -> 1898522
A28: # | B28: 3. Worst Case(Conservative Scenario) | C28: Actuals | E28: Forecast
B29: =Income_Statement_Forecast_Model[[#Headers],[P&L Line Item]] -> P&L Line Item | C29: =Income_Statement_Forecast_Model[[#Headers],[FY2019 (Actuals)]] -> FY2019 (Actuals) | D29: =Income_Statement_Forecast_Model[[#Headers],[Ratios (FY2019)]] -> Ratios (FY2019) | E29: =Income_Statement_Forecast_Model[[#Headers],[Assumptions (FY2020)]] -> Assumptions (FY2020) | F29: =Income_Statement_Forecast_Model[[#Headers],[FY2020 (Forecast)]] -> FY2020 (Forecast)
B30: =B17 -> Sales | C30: =C17 -> 5697845 | D30: =D17 -> - | E30: 0.25 | F30: =C30*(1+E30) -> 7122306.2
B31: =B18 -> Cost of Sales | C31: =C18 -> -1729299 | D31: =D18 -> 0.30350053 | E31: 0.33 | F31: =($F$30*E31)*-1 -> -2350361.1
B32: =B19 -> Gross Profit | C32: =C19 -> 3968546 | D32: =D19 -> 0.69649947 | F32: =SUM(F30:F31) -> 4771945.2
B33: =B20 -> Operating Expenses | C33: =C20 -> -1960802 | D33: =D20 -> 0.34413046 | E33: 0.36 | F33: =($F$30*E33)*-1 -> -2564030.2
B34: =B21 -> EBITDA | C34: =C21 -> 2007744 | D34: =D21 -> 0.35236901 | F34: =SUM(F32:F33) -> 2207914.9
B35: =B22 -> Depreciation & Amortization | C35: =C22 -> -532056 | D35: =D22 -> 0.093378462 | E35: 0.095 | F35: =($F$30*E35)*-1 -> -676619.09
B36: =B23 -> Non-operating | C36: =C23 -> 47162 | D36: =D23 -> 0.0082771644 | E36: 0.005 | F36: =F30*E36 -> 35611.531
B37: =B24 -> EBIT | C37: =C24 -> 1522850 | D37: =D24 -> 0.26726771 | F37: =SUM(F34:F36) -> 1566907.4
B38: =B25 -> Interest & Tax | C38: =C25 -> -219703 | D38: =D25 -> 0.038558964 | E38: 0.045 | F38: =($F$30*E38)*-1 -> -320503.78
B39: =B26 -> Net profit | C39: =C26 -> 1303147 | D39: =D26 -> 0.22870875 | F39: =SUM(F37:F38) -> 1246403.6
